Workbook
Name SegmentaciónDeDatos_Año: #N/A
Name SegmentaciónDeDatos_AÑO1: #N/A
Name SegmentaciónDeDatos_AÑO2: #N/A
Name SegmentaciónDeDatos_Factura: #N/A
Name SegmentaciónDeDatos_Factura1: #N/A
Name SegmentaciónDeDatos_Mes: #N/A
Name SegmentaciónDeDatos_MES1: #N/A

Sheet Inmuebles
B2: CONTRATO DE OBRA No PAF-ANI-O-118-2022-01 CON CONSORCIO CTSA - INGERAL - ARRENDAMIENTO DE INMUEBLES
B3: FACTURACIÓN | Q3: PAGO
B4: Año | C4: Mes | D4: Fecha | E4: # Factura CTSA - INGERAL | F4: NC | G4: Fact | H4: Corredor | I4: Tercero | J4: Periodo | K4: Inmueble - concepto | L4: Valor Facturado | M4: IVA | N4: Valor bruto | O4: 4 X 1000 | P4: Valor a Consignar a la ANI | Q4: Valor Pagado | R4: Año. | S4: Mes. | T4: Fecha. | U4: Valor Por Cobrar | V4: Observaciones
B5: =+YEAR(D5) -> 2023 | C5: =UPPER(TEXT(D5,"MMM")) -> MAY | D5: 45055 | E5: 3 | F5: NA | G5: NA | H5: Bogotá - Belencito | I5: MAQUISERVICOS | J5: 1/02/2023 - 15/04/2023 | K5: ARRIENDO DE BODEGA Y OFICINAS DE 99,11 m2, UBICADO EN EL KM5 | L5: 4465171.5 | M5: 712926.55 | N5: =L5-M5 -> 3752245 | O5: =ROUND(N5*0.004,0) -> 15009 | P5: =N5-O5 -> 3737236 | Q5: 3737236 | R5: =+YEAR(T5) -> 2023 | S5: =+MONTH(T5) -> 7 | T5: 45135 | U5: =+P5-Q5 -> 0
B6: =+YEAR(D6) -> 2023 | C6: =UPPER(TEXT(D6,"MMM")) -> MAY | D6: 45057 | E6: 4 | F6: NA | G6: NA | H6: Bogotá - Belencito | I6: CIRO | J6: 1/02/2023 - 13/03/2023 | K6: ARRIENDO DE BODEGA DE 72 M2, UBICADO EN KM 5 | L6: 1859767.7 | M6: 296937.7 | N6: =L6-M6 -> 1562830 | O6: =ROUND(N6*0.004,0) -> 6251 | P6: =N6-O6 -> 1556579 | Q6: 1556579 | R6: =+YEAR(T6) -> 2023 | S6: =+MONTH(T6) -> 7 | T6: 45135 | U6: =+P6-Q6 -> 0
B7: =+YEAR(D7) -> 2023 | C7: =UPPER(TEXT(D7,"MMM")) -> MAY | D7: 45057 | E7: 5 | F7: NA | G7: NA | H7: Bogotá - Belencito | I7: CIRO | J7: 14/03/2023 - 30/03/2023 | K7: ARRIENDO DE BODEGA DE 72 M2, UBICADO EN KM 5 | L7: 735256.97 | M7: 117393.97 | N7: =L7-M7 -> 617863 | O7: =ROUND(N7*0.004,0) -> 2471 | P7: =N7-O7 -> 615392 | Q7: 615392 | R7: =+YEAR(T7) -> 2023 | S7: =+MONTH(T7) -> 7 | T7: 45135 | U7: =+P7-Q7 -> 0
B8: =+YEAR(D8) -> 2023 | C8: =UPPER(TEXT(D8,"MMM")) -> MAY | D8: 45057 | E8: 6 | F8: NA | G8: NA | H8: Bogotá - Belencito | I8: CIRO | J8: 01/04/2023 - 30/04/2023 | K8: ARRIENDO DE BODEGA DE 72 M2, UBICADO EN KM 5 | L8: 1297511.7 | M8: 207165.74 | N8: =L8-M8 -> 1090346 | O8: =ROUND(N8*0.004,0) -> 4361 | P8: =N8-O8 -> 1085985 | Q8: 1085985 | R8: =+YEAR(T8) -> 2023 | S8: =+MONTH(T8) -> 7 | T8: 45135 | U8: =+P8-Q8 -> 0
B9: =+YEAR(D9) -> 2023 | C9: =UPPER(TEXT(D9,"MMM")) -> MAY | D9: 45057 | E9: 7 | F9: NA | G9: NA | H9: Bogotá - Belencito | I9: CIRO | J9: 01/05/2023 - 31/05/2023 | K9: ARRIENDO DE BODEGA DE 72 M2, UBICADO EN KM 5 | L9: 1297511.7 | M9: 207165.74 | N9: =L9-M9 -> 1090346 | O9: =ROUND(N9*0.004,0) -> 4361 | P9: =N9-O9 -> 1085985 | Q9: 1085985 | R9: =+YEAR(T9) -> 2023 | S9: =+MONTH(T9) -> 7 | T9: 45135 | U9: =+P9-Q9 -> 0
B10: =+YEAR(D10) -> 2023 | C10: =UPPER(TEXT(D10,"MMM")) -> MAY | D10: 45077 | E10: 9 | F10: 19 | G10: 9 | H10: Bogotá - Belencito | I10: CEMENTOS ARGOS | J10: 1/02/2023 - 13/03/2023 | K10: ARRIENDO BODEGA CON UNA ÁREA DE 2.234 M2 UBICADA EN KM5 | L10: 64206895 | M10: 10251521 | N10: =L10-M10 -> 53955374 | O10: =ROUND(N10*0.004,0) -> 215821 | P10: =N10-O10 -> 53739553 | U10: =+P10-Q10 -> 53739553
B11: =+YEAR(D11) -> 2023 | C11: =UPPER(TEXT(D11,"MMM")) -> MAY | D11: 45077 | E11: 10 | F11: 20 | G11: 10 | H11: Bogotá - Belencito | I11: CEMENTOS ARGOS | J11: 14/03/2023 - 30/03/2023 | K11: ARRIENDO BODEGA CON UNA ÁREA DE 2.234 M2 UBICADA EN KM5 | L11: 25384111 | M11: 4052925.3 | N11: =L11-M11 -> 21331186 | O11: =ROUND(N11*0.004,0) -> 85325 | P11: =N11-O11 -> 21245861 | U11: =+P11-Q11 -> 21245861
B12: =+YEAR(D12) -> 2023 | C12: =UPPER(TEXT(D12,"MMM")) -> MAY | D12: 45077 | E12: 11 | F12: 21 | G12: 11 | H12: Bogotá - Belencito | I12: CEMENTOS ARGOS | J12: 01/04/2023 - 30/04/2023 | K12: ARRIENDO BODEGA CON UNA ÁREA DE 2.234 M2 UBICADA EN KM5 | L12: 44795503 | M12: 7152223.2 | N12: =L12-M12 -> 37643280 | O12: =ROUND(N12*0.004,0) -> 150573 | P12: =N12-O12 -> 37492707 | U12: =+P12-Q12 -> 37492707
B13: =+YEAR(D13) -> 2023 | C13: =UPPER(TEXT(D13,"MMM")) -> MAY | D13: 45077 | E13: 12 | F13: 22 | G13: 12 | H13: Bogotá - Belencito | I13: CEMENTOS ARGOS | J13: 01/05/2023 - 31/05/2023 | K13: ARRIENDO BODEGA CON UNA ÁREA DE 2.234 M2 UBICADA EN KM5 | L13: 44795503 | M13: 7152223.2 | N13: =L13-M13 -> 37643280 | O13: =ROUND(N13*0.004,0) -> 150573 | P13: =N13-O13 -> 37492707 | U13: =+P13-Q13 -> 37492707
B14: =+YEAR(D14) -> 2023 | C14: =UPPER(TEXT(D14,"MMM")) -> JUN | D14: 45084 | E14: 16 | F14: NA | G14: NA | H14: Bogotá - Belencito | I14: CIRO | J14: 01/06/2023 - 30/06/2023 | K14: ARRIENDO DE BODEGA DE 72 M2, UBICADO EN KM 5 | L14: 1297511.7 | M14: 207165.74 | N14: =L14-M14 -> 1090346 | O14: =ROUND(N14*0.004,0) -> 4361 | P14: =N14-O14 -> 1085985 | Q14: 1085985 | R14: =+YEAR(T14) -> 2023 | S14: =+MONTH(T14) -> 7 | T14: 45135 | U14: =+P14-Q14 -> 0
B15: =+YEAR(D15) -> 2023 | C15: =UPPER(TEXT(D15,"MMM")) -> JUN | D15: 45084 | E15: 17 | F15: NA | G15: NA | H15: Bogotá - Belencito | I15: CEMENTOS ARGOS | J15: 01/06/2023 - 30/06/2023 | K15: ARRIENDO BODEGA CON UNA ÁREA DE 2.234 M2 UBICADA EN KM5 | L15: 44795503 | M15: 7152223.2 | N15: =L15-M15 -> 37643280 | O15: =ROUND(N15*0.004,0) -> 150573 | P15: =N15-O15 -> 37492707 | Q15: 37492707 | R15: 2023 | S15: 10 | T15: 45204 | U15: =+P15-Q15 -> 0.28
B16: =+YEAR(D16) -> 2023 | C16: =UPPER(TEXT(D16,"MMM")) -> JUN | D16: 45084 | E16: 17 | F16: NA | G16: NA | H16: Bogotá - Belencito | I16: CEMENTOS ARGOS | J16: 01/06/2023 - 30/06/2023 | K16: ARRIENDO BODEGA CON UNA ÁREA DE 2.234 M2 UBICADA EN KM6 | Q16: 0.28 | R16: 2023 | S16: 11 | T16: 45233 | U16: =P16-Q16 -> -0.28
B17: =+YEAR(D17) -> 2023 | C17: =UPPER(TEXT(D17,"MMM")) -> JUN | D17: 45103 | E17: 25 | F17: 8 | G17: 25 | H17: Bogotá - Belencito | I17: Fideicomiso Sociedad Fiduciaria de occidente | J17: 1/02/2023 - 13/03/2023 | K17: ARRIENDO DE BODEGA DE 128,2 M2, UBICADO EN KM 5 | L17: 4053414.9 | M17: 647183.89 | N17: =L17-M17 -> 3406231 | O17: =ROUND(N17*0.004,0) -> 13625 | P17: =N17-O17 -> 3392606 | U17: =+P17-Q17 -> 3392606 | V17: Como la factura 25 se anulo, se reemplaza por la factura 41
B18: =+YEAR(D18) -> 2023 | C18: =UPPER(TEXT(D18,"MMM")) -> JUN | D18: 45103 | E18: 26 | F18: 9 | G18: 26 | H18: Bogotá - Belencito | I18: Fideicomiso Sociedad Fiduciaria de occidente | J18: 14/03/2023 - 30/03/2023 | K18: ARRIENDO DE BODEGA DE 128,2 M2, UBICADO EN KM 5 | L18: 1602512.3 | M18: 255863.31 | N18: =L18-M18 -> 1346649 | O18: =ROUND(N18*0.004,0) -> 5387 | P18: =N18-O18 -> 1341262 | U18: =+P18-Q18 -> 1341262 | V18: Como la factura 26 se anulo, se reemplaza por la factura 42
B19: =+YEAR(D19) -> 2023 | C19: =UPPER(TEXT(D19,"MMM")) -> JUN | D19: 45103 | E19: 27 | F19: 10 | G19: 27 | H19: Bogotá - Belencito | I19: Fideicomiso Sociedad Fiduciaria de occidente | J19: 01/04/2023 - 30/04/2023 | K19: ARRIENDO DE BODEGA DE 128,2 M2, UBICADO EN KM 5 | L19: 2827963.6 | M19: 451523.6 | N19: =L19-M19 -> 2376440 | O19: =ROUND(N19*0.004,0) -> 9506 | P19: =N19-O19 -> 2366934 | U19: =+P19-Q19 -> 2366934 | V19: Como la factura 27 se anulo, se reemplaza por la factura 43
B20: =+YEAR(D20) -> 2023 | C20: =UPPER(TEXT(D20,"MMM")) -> JUN | D20: 45103 | E20: 28 | F20: NA | G20: NA | H20: Bogotá - Belencito | I20: Fideicomiso Sociedad Fiduciaria de occidente | J20: 01/05/2023 - 30/05/2023 | K20: ARRIENDO DE BODEGA DE 128,2 M2, UBICADO EN KM 5 | L20: 2827963.6 | M20: 451523.6 | N20: =+L20-M20 -> 2376440 | O20: =ROUND(N20*0.004,0) -> 9506 | P20: =N20-O20 -> 2366934 | U20: =+P20-Q20 -> 2366934 | V20: Como la factura 28 se anulo, se reemplaza por la factura 44
B21: =+YEAR(D21) -> 2023 | C21: =UPPER(TEXT(D21,"MMM")) -> JUN | D21: 45103 | E21: 29 | F21: NA | G21: NA | H21: Bogotá - Belencito | I21: Fideicomiso Sociedad Fiduciaria de occidente | J21: 01/06/2023 - 30/06/2023 | K21: ARRIENDO DE BODEGA DE 128,2 M2, UBICADO EN KM 5 | L21: 2827963.6 | M21: 451523.6 | N21: =+L21-M21 -> 2376440 | O21: =ROUND(N21*0.004,0) -> 9506 | P21: =N21-O21 -> 2366934 | U21: =+P21-Q21 -> 2366934 | V21: Como la factura 29 se anulo, se reemplaza por la factura 45
B22: =+YEAR(D22) -> 2023 | C22: =UPPER(TEXT(D22,"MMM")) -> JUL | D22: 45112 | E22: 31 | F22: NA | G22: NA | H22: Bogotá - Belencito | I22: CEMENTOS ARGOS | J22: 45125 | K22: ARRIENDO BODEGA CON UNA ÁREA DE 2.234 M2 UBICADA EN KM5 | L22: 44795503 | M22: 7152223.2 | N22: =L22-M22 -> 37643280 | O22: =ROUND(N22*0.004,0) -> 150573 | P22: =N22-O22 -> 37492707 | Q22: 37492707 | R22: 2023 | S22: 10 | T22: 45204 | U22: =+P22-Q22 -> 0.28
B23: =+YEAR(D23) -> 2023 | C23: =UPPER(TEXT(D23,"MMM")) -> JUL | D23: 45112 | E23: 31 | F23: NA | G23: NA | H23: Bogotá - Belencito | I23: CEMENTOS ARGOS | J23: 45125 | K23: ARRIENDO BODEGA CON UNA ÁREA DE 2.234 M2 UBICADA EN KM6 | Q23: 0.28 | R23: 2023 | S23: 11 | T23: 45233 | U23: =P23-Q23 -> -0.28
B24: =+YEAR(D24) -> 2023 | C24: =UPPER(TEXT(D24,"MMM")) -> JUL | D24: 45112 | E24: 32 | F24: NA | G24: NA | H24: Bogotá - Belencito | I24: CIRO | J24: 45130 | K24: ARRIENDO DE BODEGA DE 72 M2, UBICADO EN KM 5 | L24: 1297511.7 | M24: 207165.74 | N24: =+L24-M24 -> 1090346 | O24: =ROUND(N24*0.004,0) -> 4361 | P24: =N24-O24 -> 1085985 | Q24: 1085985 | R24: =+YEAR(T24) -> 2023 | S24: =+MONTH(T24) -> 7 | T24: 45135 | U24: =+P24-Q24 -> 0
B25: =+YEAR(D25) -> 2023 | C25: =UPPER(TEXT(D25,"MMM")) -> JUL | D25: 45108 | E25: Nota crédito No.2-8 del 28 de junio de 2023 | F25: 8 | G25: 25 | H25: Bogotá - Belencito | I25: Fideicomiso Sociedad Fiduciaria de occidente | J25: 1/02/2023 - 13/03/2023 | K25: Nota de Crédito No. 8 para anular factura 25 ARRIENDO DE BODEGA DE 128,2 M2, UBICADO EN KM 5 porque la legalización del contrato de arrendamiento se realizo en el periodo 1/02/2023 al 13/03/2023 | L25: -4053414.9 | M25: -647183.89 | N25: =L25-M25 -> -3406231 | O25: =ROUND(N25*0.004,0) -> -13625 | P25: =N25-O25 -> -3392606 | U25: =+P25-Q25 -> -3392606
B26: =+YEAR(D26) -> 2023 | C26: =UPPER(TEXT(D26,"MMM")) -> JUL | D26: 45108 | E26: Nota crédito No.2-9 del 28 de junio de 2023 | F26: 9 | G26: 26 | H26: Bogotá - Belencito | I26: Fideicomiso Sociedad Fiduciaria de occidente | J26: 14/03/2023 - 30/03/2023 | K26: Nota de Crédito No.9 para anular factura No. 26 ARRIENDO DE BODEGA DE 128,2 M2, UBICADO EN KM 5 porque la legalización del contrato de arrendamiento se realizo en el periodo del 14 al 30 marzo de 2023. | L26: -1602512.3 | M26: -255863.31 | N26: -1346649 | O26: =ROUND(N26*0.004,0) -> -5387 | P26: =N26-O26 -> -1341262 | U26: =+P26-Q26 -> -1341262
B27: =+YEAR(D27) -> 2023 | C27: =UPPER(TEXT(D27,"MMM")) -> JUL | D27: 45108 | E27: Nota crédito No.2-10 del 28 de junio de 2023 | F27: 10 | G27: 27 | H27: Bogotá - Belencito | I27: Fideicomiso Sociedad Fiduciaria de occidente | J27: 01/04/2023 - 30/04/2023 | K27: Nota Crédito No. 10 para analuar Factura 27. ARRIENDO DE BODEGA DE 128,2 M2, UBICADO EN KM 5 porque la legalización del contrato de arrendamiento se realizo en el mes de abril de 2023 | L27: -2827963.6 | M27: -451523.6 | N27: =+L27-M27 -> -2376440 | O27: =ROUND(N27*0.004,0) -> -9506 | P27: =N27-O27 -> -2366934 | U27: =+P27-Q27 -> -2366934
B28: =+YEAR(D28) -> 2023 | C28: =UPPER(TEXT(D28,"MMM")) -> JUL | D28: 45108 | E28: Nota credito No.2-11 del 28 de junio de 2023 | F28: 11 | G28: 28 | H28: Bogotá - Belencito | I28: Fideicomiso Sociedad Fiduciaria de occidente | J28: 01/05/2023 - 31/05/2023 | K28: Nota Crédito No, 11 para anular factura 28 ARRIENDO DE BODEGA DE 128,2 M2, UBICADO EN KM 5 porque la legalización del contrato de arrendamiento se realizo en el mes de mayo de 2023 | L28: -2827963.6 | M28: -451523.6 | N28: =L28-M28 -> -2376440 | O28: =ROUND(N28*0.004,0) -> -9506 | P28: =N28-O28 -> -2366934 | U28: =+P28-Q28 -> -2366934
B29: =+YEAR(D29) -> 2023 | C29: =UPPER(TEXT(D29,"MMM")) -> JUL | D29: 45108 | E29: Nota credito No.2-12 del 28 de junio de 2023 | F29: 12 | G29: 29 | H29: Bogotá - Belencito | I29: Fideicomiso Sociedad Fiduciaria de occidente | J29: 01/06/2023 - 30/06/2023 | K29: Nota Crédito No.12 para anular factura 29 ARRIENDO DE BODEGA DE 128,2 M2, UBICADO EN KM 5 porque la legalización del contrato de arrendamiento se realizo en el mes de junio de 2023 | L29: -2827963.6 | M29: -451523.6 | N29: =L29-M29 -> -2376440 | O29: =ROUND(N29*0.004,0) -> -9506 | P29: =N29-O29 -> -2366934 | U29: =+P29-Q29 -> -2366934
B30: 2023 | C30: =UPPER(TEXT(D30,"MMM")) -> JUL | D30: 45125 | E30: 41 | F30: NA | G30: NA | H30: Bogotá - Belencito | I30: Fideicomiso Sociedad Fiduciaria de occidente | J30: 1/02/2023 - 13/03/2023 | K30: ARRIENDO DE BODEGA DE 128,2 M2, UBICADO EN KM 5 | L30: 4053414.9 | M30: 647183.89 | N30: 3406231 | O30: =ROUND(N30*0.004,0) -> 13625 | P30: =N30-O30 -> 3392606 | Q30: 3392606 | R30: 2023 | S30: 8 | T30: 45168 | U30: =+P30-Q30 -> 0 | V30: La factura 19 y 25 son reemplazadas porla factura 41. Como se anularon las facturas 19 y 25, por lo cual se carga la consigancion a la factura 41
B31: 2023 | C31: =UPPER(TEXT(D31,"MMM")) -> JUL | D31: 45125 | E31: 42 | F31: NA | G31: NA | H31: Bogotá - Belencito | I31: Fideicomiso Sociedad Fiduciaria de occidente | J31: 14/03/2023 - 30/03/2023 | K31: ARRIENDO DE BODEGA DE 128,2 M2, UBICADO EN KM 5 | L31: 1602512.3 | M31: 255863.31 | N31: 1346649 | O31: =ROUND(N31*0.004,0) -> 5387 | P31: =N31-O31 -> 1341262 | Q31: 1341262 | R31: 2023 | S31: 8 | T31: 45168 | U31: =+P31-Q31 -> 0 | V31: La factura 20 y 26 son reemplazadas porla factura 42. Como se anularon las facturas 20 y 26, por lo cual se carga la consigancion a la factura 42
B32: 2023 | C32: =UPPER(TEXT(D32,"MMM")) -> JUL | D32: 45125 | E32: 43 | F32: NA | G32: NA | H32: Bogotá - Belencito | I32: Fideicomiso Sociedad Fiduciaria de occidente | J32: 01/04/2023 - 30/04/2023 | K32: ARRIENDO DE BODEGA DE 128,2 M2, UBICADO EN KM 5 | L32: 2827963.6 | M32: 451523.6 | N32: 2376440 | O32: =ROUND(N32*0.004,0) -> 9506 | P32: =N32-O32 -> 2366934 | Q32: 2366934 | R32: 2023 | S32: 8 | T32: 45168 | U32: =+P32-Q32 -> 0 | V32: La factura 21 y 27 son reemplazadas porla factura 43. Como se anularon las facturas 21 y 27, por lo cual se carga la consigancion a la factura 43
B33: 2023 | C33: =UPPER(TEXT(D33,"MMM")) -> JUL | D33: 45125 | E33: 44 | F33: NA | G33: NA | H33: Bogotá - Belencito | I33: Fideicomiso Sociedad Fiduciaria de occidente | J33: 01/05/2023 - 30/05/2023 | K33: ARRIENDO DE BODEGA DE 128,2 M2, UBICADO EN KM 5 | L33: 2827963.6 | M33: 451523.6 | N33: 2376440 | O33: =ROUND(N33*0.004,0) -> 9506 | P33: =N33-O33 -> 2366934 | Q33: 2366934 | R33: =+YEAR(T33) -> 2023 | S33: =+MONTH(T33) -> 8 | T33: 45168 | U33: =+P33-Q33 -> 0 | V33: La factura 22 y 28 son reemplazadas porla factura 44. Como se anularon las facturas 22 y 28, por lo cual se carga la consigancion a la factura 44
B34: 2023 | C34: =UPPER(TEXT(D34,"MMM")) -> JUL | D34: 45125 | E34: 45 | F34: NA | G34: NA | H34: Bogotá - Belencito | I34: Fideicomiso Sociedad Fiduciaria de occidente | J34: 01/06/2023 - 30/06/2023 | K34: ARRIENDO DE BODEGA DE 128,2 M2, UBICADO EN KM 5 | L34: 2827963.6 | M34: 451523.6 | N34: 2376440 | O34: =ROUND(N34*0.004,0) -> 9506 | P34: =N34-O34 -> 2366934 | Q34: 2366934 | R34: 2023 | S34: 8 | T34: 45168 | U34: =+P34-Q34 -> 0 | V34: La factura 18 y 29 son reemplazadas porla factura 45. Como se anularon las facturas 18 y 29, por lo cual se carga la consigancion a la factura 45
B35: =+YEAR(D35) -> 2023 | C35: =UPPER(TEXT(D35,"MMM")) -> JUL | D35: 45125 | E35: 46 | F35: NA | G35: NA | H35: Bogotá - Belencito | I35: Fideicomiso Sociedad Fiduciaria de occidente | J35: 1/07/2023 - 30/07/2023 | K35: ARRIENDO DE BODEGA DE 128,2 M2, UBICADO EN KM 5 | L35: 2827963.6 | M35: 451523.6 | N35: =L35-M35 -> 2376440 | O35: =ROUND(N35*0.004,0) -> 9506 | P35: =N35-O35 -> 2366934 | Q35: 2366934 | R35: =+YEAR(T35) -> 2023 | S35: =+MONTH(T35) -> 8 | T35: 45168 | U35: =+P35-Q35 -> 0
B36: =+YEAR(D36) -> 2023 | C36: =UPPER(TEXT(D36,"MMM")) -> JUL | D36: 45132 | E36: Nota credito No.2-19 | F36: 19 | G36: 9 | H36: Bogotá - Belencito | I36: CEMENTOS ARGOS | J36: 1/02/2023 - 13/03/2023 | K36: Nota Crédito No. 19 para anular factura 9 ARRIENDO BODEGA CON UNA AREA DE 2.234 M2 UBICADA EN KM5, porque la legalización del contrati de arrendamiento se realizo en el periodo 1/02/2023 al 13/03/2023 | L36: -64206895 | M36: -10251521 | N36: =L36-M36 -> -53955374 | O36: =ROUND(N36*0.004,0) -> -215821 | P36: =N36-O36 -> -53739553 | U36: =+P36-Q36 -> -53739553
B37: =+YEAR(D37) -> 2023 | C37: =UPPER(TEXT(D37,"MMM")) -> JUL | D37: 45132 | E37: Nota credito No.2-20 | F37: 20 | G37: 10 | H37: Bogotá - Belencito | I37: CEMENTOS ARGOS | J37: 14/03/2023 - 30/03/2023 | K37: Nota Crédicto No.20 para anular factura 10 ARRIENDO BODEGA CON UNA AREA DE 2.234 M2 UBICADA EN KM5, porque la legalización del contrati de arrendamiento se realizo en el mes de marzo de 2023 | L37: -25384111 | M37: -4052925.3 | N37: =L37-M37 -> -21331186 | O37: =ROUND(N37*0.004,0) -> -85325 | P37: =N37-O37 -> -21245861 | U37: =+P37-Q37 -> -21245861
B38: =+YEAR(D38) -> 2023 | C38: =UPPER(TEXT(D38,"MMM")) -> JUL | D38: 45132 | E38: Nota credito No.2-21 | F38: 21 | G38: 11 | H38: Bogotá - Belencito | I38: CEMENTOS ARGOS | J38: 01/04/2023 - 30/04/2023 | K38: Nota Crédito No.21 para anular factura 11 ARRIENDO BODEGA CON UNA AREA DE 2.234 M2 UBICADA EN KM5, porque la legalización del contrati de arrendamiento se realizo en el mes de abril de 2023 | L38: -44795503 | M38: -7152223.2 | N38: =L38-M38 -> -37643280 | O38: =ROUND(N38*0.004,0) -> -150573 | P38: =N38-O38 -> -37492707 | U38: =+P38-Q38 -> -37492707
B39: =+YEAR(D39) -> 2023 | C39: =UPPER(TEXT(D39,"MMM")) -> JUL | D39: 45132 | E39: Nota credito No.2-22 | F39: 22 | G39: 12 | H39: Bogotá - Belencito | I39: CEMENTOS ARGOS | J39: 01/05/2023 - 31/05/2023 | K39: Nota de Crédito No.22 para anular factura 12 ARRIENDO BODEGA CON UNA AREA DE 2.234 M2 UBICADA EN KM5, porque la legalización del contrati de arrendamiento se realizo en el mes de mayo de 2023 | L39: -44795503 | M39: -7152223.2 | N39: =L39-M39 -> -37643280 | O39: =ROUND(N39*0.004,0) -> -150573 | P39: =N39-O39 -> -37492707 | U39: =+P39-Q39 -> -37492707
B40: 2023 | C40: =UPPER(TEXT(D40,"MMM")) -> JUL | D40: 45132 | E40: 48 | F40: NA | G40: NA | H40: Bogotá - Belencito | I40: CEMENTOS ARGOS | J40: 1/02/2023 - 13/03/2023 | K40: ARRIENDO BODEGA CON UNA AREA DE 2.234 M2 UBICADA EN KM5 | L40: 64206895 | M40: 10251521 | N40: 53955374 | O40: =ROUND(N40*0.004,0) -> 215821 | P40: =N40-O40 -> 53739553 | Q40: 53739553 | R40: =+YEAR(T40) -> 2023 | S40: =+MONTH(T40) -> 8 | T40: 45168 | U40: =+P40-Q40 -> 0 | V40: Como se anulo la factura 9, por lo cual se carga la consigancion a la factura 48
B41: 2023 | C41: =UPPER(TEXT(D41,"MMM")) -> JUL | D41: 45132 | E41: 49 | F41: NA | G41: NA | H41: Bogotá - Belencito | I41: CEMENTOS ARGOS | J41: 14/03/2023 - 30/03/2023 | K41: ARRIENDO BODEGA CON UNA AREA DE 2.234 M2 UBICADA EN KM5 | L41: 25384111 | M41: 4052925.3 | N41: 21331186 | O41: =ROUND(N41*0.004,0) -> 85325 | P41: =N41-O41 -> 21245861 | Q41: 21245861 | R41: 2023 | S41: 8 | T41: 45168 | U41: =+P41-Q41 -> 0 | V41: Como se anulo la factura 10, por lo cual se carga la consigancion a la factura 49
...

Sheet Tabla Inm.
K1: Inmuebles
A2: Etiquetas de fila | B2: Suma de Valor a Consignar a la ANI | C2: Suma de Valor Pagado | F2: Etiquetas de fila | G2: Suma de Valor a Consignar a la ANI | H2: Suma de Valor Pagado | K2: Etiquetas de fila | L2: Suma de Valor Pagado
A3: ENE | B3: 71784134 | C3: 71385121 | F3: CEMENTOS ARGOS | G3: 2.2964201e+08 | H3: 74473617 | K3: ENE | L3: 1.3872838e+08
A4: 2025 | B4: 71784134 | C4: 71385121 | F4: 2025 | G4: 2.2964201e+08 | H4: 74473617 | K4: 2024 | L4: 66944242
A5: FEB | B5: 71784134 | C5: 71784134 | F5: Fideicomiso Sociedad Fiduciaria de occidente | G5: 95007126 | H5: 45546709 | K5: 2025 | L5: 71385121
A6: 2025 | B6: 71784134 | C6: 71784134 | F6: 2025 | G6: 95007126 | H6: 45546709 | K6: 2026 | L6: 399013.4
A7: MAR | B7: 85107637 | C7: 72584734 | F7: Turistren | G7: 3.1850823e+08 | H7: 1.0616941e+08 | K7: FEB | L7: 1.3474438e+08
A8: 2025 | B8: 85107637 | C8: 72584734 | F8: 2025 | G8: 3.1850823e+08 | H8: 1.0616941e+08 | K8: 2024 | L8: 62960242
A9: ABR | B9: 79067067 | C9: 10435748 | F9: JE JAIMES Ingenieros S.A.S | G9: 25516994 | K9: 2025 | L9: 71784134
A10: 2025 | B10: 79067067 | C10: 10435748 | F10: 2025 | G10: 25516994 | K10: MAR | L10: 1.3554498e+08
A11: MAY | B11: 79067067 | F11: Total general | G11: 6.6867436e+08 | H11: 2.2618974e+08 | K11: 2024 | L11: 62960242
A12: 2025 | B12: 79067067 | K12: 2025 | L12: 72584734
A13: JUN | B13: 73510424 | K13: ABR | L13: 77379990
A14: 2025 | B14: 73510424 | K14: 2024 | L14: 66944242
A15: JUL | B15: 71074948 | K15: 2025 | L15: 10435748
A16: 2025 | B16: 71074948 | K16: MAY | L16: 82993419
A17: AGO | B17: 68639473 | K17: 2023 | L17: 8081177
A18: 2025 | B18: 68639473 | K18: 2024 | L18: 74912242
A19: SEP | B19: 68639473 | K19: 2025
A20: 2025 | B20: 68639473 | K20: JUN | L20: 1.0552293e+08
A21: Total general | B21: 6.6867436e+08 | C21: 2.2618974e+08 | K21: 2023 | L21: 38578692
K22: 2024 | L22: 66944242
K23: 2025
K24: JUL | L24: 2.720026e+08
K25: 2023 | L25: 2.0275112e+08
K26: 2024 | L26: 69251475
K27: 2025
K28: AGO | L28: 72843567
K29: 2023 | L29: 3452919.6
K30: 2024 | L30: 69390647
K31: 2025
K32: SEP | L32: 72704394
K33: 2023 | L33: 3452919.6
K34: 2024 | L34: 69251475
K35: 2025
K36: OCT | L36: 1.8558028e+08
K37: 2023 | L37: 1.1593041e+08
K38: 2024 | L38: 69649875
K39: NOV | L39: 74646572
K40: 2023
...

Sheet Imuebles 2

Sheet Uso de Via
A1: CONTRATO DE OBRA No PAF-ANI-O-118-2022-01 CON CONSORCIO CTSA - INGERAL - USO DE VIA
A2: FACTURACIÓN | Q2: PAGO
A3: Año | B3: Mes | C3: Fecha | D3: # Factura | E3: Corredor | F3: Tercero | G3: Periodo | H3: Concepto | I3: # Toneladas -kilometro | J3: # coche-kilómetros | K3: Tarifas $/ton-km y/o tarifa $/coche-km | L3: Valor Facturado | M3: IVA | N3: Valor bruto | O3: 4X1000 | P3: Valor a Consignar a la ANI | Q3: Valor Pagado | R3: Año2 | S3: Mes3 | T3: Fecha4 | U3: Valor Por Cobrar
A4: =+YEAR(C4) -> 2023 | B4: =UPPER(TEXT(C4,"MMM")) -> MAY | C4: 45055 | D4: 2 | E4: Bogotá - Belencito | F4: TURISTREN | G4: 17/03/2023 - 31/03/2023 | H4: USO DE VÍA PASAJEROS | J4: =+L4/K4 -> 11190 | K4: 850.96 | L4: 9522242 | N4: =L4-M4 -> 9522242 | O4: =ROUND(N4*0.004,0) -> 38089 | P4: =(N4-O4) -> 9484153 | Q4: 9484153 | R4: 2023 | S4: =UPPER(TEXT(T4,"MMM")) -> JUN | T4: 45085 | U4: =+P4-Q4 -> 0
A5: =+YEAR(C5) -> 2023 | B5: =UPPER(TEXT(C5,"MMM")) -> MAY | C5: 45070 | D5: 8 | E5: Bogotá - Belencito | F5: TURISTREN | G5: 01/04/2023 - 30/04/2023 | H5: USO DE VÍA PASAJEROS | J5: =+L5/K5 -> 43724 | K5: 850.96 | L5: 37207375 | N5: =L5-M5 -> 37207375 | O5: =ROUND(N5*0.004,0) -> 148830 | P5: =(N5-O5) -> 37058545 | Q5: 37058545 | R5: 2023 | S5: =UPPER(TEXT(T5,"MMM")) -> JUN | T5: 45085 | U5: =+P5-Q5 -> 0
A6: =+YEAR(C6) -> 2023 | B6: =UPPER(TEXT(C6,"MMM")) -> JUN | C6: 45078 | D6: 13 | E6: Bogotá - Belencito | F6: TURISTREN | G6: 01/05/2023 - 31/05/2023 | H6: USO DE VÍA PASAJEROS | J6: =+L6/K6 -> 46998 | K6: 850.96 | L6: 39993418 | N6: =L6-M6 -> 39993418 | O6: =ROUND(N6*0.004,0) -> 159974 | P6: =(N6-O6) -> 39833444 | Q6: 39833444 | R6: =+YEAR(T6) -> 2023 | S6: =UPPER(TEXT(T6,"MMM")) -> JUL | T6: 45135 | U6: =+P6-Q6 -> 0
A7: =+YEAR(C7) -> 2023 | B7: =UPPER(TEXT(C7,"MMM")) -> JUN | C7: 45107 | D7: OC001 | E7: Bogotá - Belencito | F7: CTSA-INGERAL | G7: 01/06/2023 - 30/06/2023 | H7: USO DE VÍA CARGA | I7: =ROUND(+L7/K7,0) -> 800917 | K7: 8 | L7: 6407339 | M7: 0 | N7: =L7-M7 -> 6407339 | O7: =ROUND(N7*0.004,0) -> 25629 | P7: =(N7-O7) -> 6381710 | Q7: 6381710 | R7: =+YEAR(T7) -> 2023 | S7: =UPPER(TEXT(T7,"MMM")) -> JUL | T7: 45135 | U7: =+P7-Q7 -> 0
A8: =+YEAR(C8) -> 2023 | B8: =UPPER(TEXT(C8,"MMM")) -> JUL | C8: 45111 | D8: 30 | E8: Bogotá - Belencito | F8: TURISTREN | G8: 01/06/2023 - 30/06/2023 | H8: USO DE VÍA PASAJEROS | J8: =+L8/K8 -> 20328 | K8: 850.96 | L8: 17298315 | N8: =L8-M8 -> 17298315 | O8: =ROUND(N8*0.004,0) -> 69193 | P8: =(N8-O8) -> 17229122 | Q8: 17229122 | R8: =+YEAR(T8) -> 2023 | S8: =UPPER(TEXT(T8,"MMM")) -> JUL | T8: 45135 | U8: =+P8-Q8 -> 0
A9: =+YEAR(C9) -> 2023 | B9: =UPPER(TEXT(C9,"MMM")) -> JUL | C9: 45138 | D9: OC002 | E9: Bogotá - Belencito | F9: CTSA-INGERAL | G9: 01/07/2023 - 30/07/2023 | H9: USO DE VÍA CARGA | I9: =ROUND(+L9/K9,0) -> 1003665 | K9: 8 | L9: 8029317 | N9: =L9-M9 -> 8029317 | O9: =ROUND(N9*0.004,0) -> 32117 | P9: =(N9-O9) -> 7997200 | Q9: 4001104 | R9: =+YEAR(T9) -> 2023 | S9: =UPPER(TEXT(T9,"MMM")) -> JUL | T9: 45135 | U9: =+P9-Q9 -> 3996096
A10: =+YEAR(C10) -> 2023 | B10: =UPPER(TEXT(C10,"MMM")) -> JUL | C10: 45138 | D10: OC002 | E10: Bogotá - Belencito | F10: CTSA-INGERAL | G10: 01/07/2023 - 30/07/2023 | H10: USO DE VÍA CARGA | I10: =ROUND(+L10/K10,0) -> 0 | K10: 8 | L10: 0 | N10: =L10-M10 -> 0 | O10: =ROUND(N10*0.004,0) -> 0 | P10: =(N10-O10) -> 0 | Q10: 3996096 | R10: =+YEAR(T10) -> 2023 | S10: =UPPER(TEXT(T10,"MMM")) -> AGO | T10: 45142 | U10: =+P10-Q10 -> -3996096
A11: =+YEAR(C11) -> 2023 | B11: =UPPER(TEXT(C11,"MMM")) -> AGO | C11: 45140 | D11: 53 | E11: Bogotá - Belencito | F11: TURISTREN | G11: 01/07/2023 - 30/07/2023 | H11: USO DE VÍA PASAJEROS | J11: =+L11/K11 -> 27108 | K11: 850.96 | L11: 23067824 | N11: =L11-M11 -> 23067824 | O11: =ROUND(N11*0.004,0) -> 92271 | P11: =(N11-O11) -> 22975553 | Q11: 22975553 | R11: =+YEAR(T11) -> 2023 | S11: =UPPER(TEXT(T11,"MMM")) -> AGO | T11: 45168 | U11: =+P11-Q11 -> 0
A12: =+YEAR(C12) -> 2023 | B12: =UPPER(TEXT(C12,"MMM")) -> AGO | C12: 45169 | D12: OC003 | E12: Bogotá - Belencito | F12: CTSA-INGERAL | G12: 01/07/2023 - 30/07/2023 | H12: USO DE VÍA CARGA | I12: =ROUND(+L12/K12,0) -> 801545 | K12: 8 | L12: 6412356 | N12: =L12-M12 -> 6412356 | O12: =ROUND(N12*0.004,0) -> 25649 | P12: =(N12-O12) -> 6386707 | Q12: 3996096 | R12: =+YEAR(T12) -> 2023 | S12: =UPPER(TEXT(T12,"MMM")) -> AGO | T12: 45168 | U12: =+P12-Q12 -> 2390611
A13: =+YEAR(C13) -> 2023 | B13: =UPPER(TEXT(C13,"MMM")) -> AGO | C13: 45169 | D13: 60 | E13: Bogotá - Belencito | F13: TURISTREN | G13: 01/08/2023 - 30/08/2023 | H13: USO DE VÍA PASAJEROS | J13: =+L13/K13 -> 41113.999 | K13: 850.96 | L13: 34986369 | N13: =L13-M13 -> 34986369 | O13: =ROUND(N13*0.004,0) -> 139945 | P13: =(N13-O13) -> 34846424 | Q13: 34846424 | R13: 2023 | S13: =UPPER(TEXT(T13,"MMM")) -> OCT | T13: 45204 | U13: =+P13-Q13 -> 0
A14: =+YEAR(C14) -> 2023 | B14: =UPPER(TEXT(C14,"MMM")) -> AGO | C14: 45169 | D14: OC003 | E14: Bogotá - Belencito | F14: CTSA-INGERAL | G14: 01/07/2023 - 30/07/2023 | H14: USO DE VÍA CARGA | I14: =ROUND(+L14/K14,0) -> 0 | K14: 8 | Q14: 2390611 | R14: =+YEAR(T14) -> 2023 | S14: =UPPER(TEXT(T14,"MMM")) -> NOV | T14: 45233 | U14: =P14-Q14 -> -2390611
A15: =+YEAR(C15) -> 2023 | B15: =UPPER(TEXT(C15,"MMM")) -> SEP | C15: 45199 | D15: OC004 | E15: Bogotá - Belencito | F15: CTSA-INGERAL | G15: 01/09/2023 - 30/09/2023 | H15: USO DE VÍA CARGA | I15: =ROUND(+L15/K15,0) -> 901672 | K15: 8 | L15: 7213373 | N15: =L15-M15 -> 7213373 | O15: =ROUND(N15*0.004,0) -> 28853 | P15: =(N15-O15) -> 7184520 | Q15: 7184520 | R15: =+YEAR(T15) -> 2023 | S15: =UPPER(TEXT(T15,"MMM")) -> NOV | T15: 45233 | U15: =+P15-Q15 -> 0
A16: =+YEAR(C16) -> 2023 | B16: =UPPER(TEXT(C16,"MMM")) -> SEP | C16: 45199 | D16: 73 | E16: Bogotá - Belencito | F16: TURISTREN | G16: 01/09/2023 - 30/09/2023 | H16: USO DE VÍA PASAJEROS | J16: =+L16/K16 -> 37822 | K16: 850.96 | L16: 32185009 | N16: =L16-M16 -> 32185009 | O16: =ROUND(N16*0.004,0) -> 128740 | P16: =(N16-O16) -> 32056269 | Q16: 32056269 | R16: =+YEAR(T16) -> 2023 | S16: =UPPER(TEXT(T16,"MMM")) -> NOV | T16: 45233 | U16: =+P16-Q16 -> 0
A17: =+YEAR(C17) -> 2023 | B17: =UPPER(TEXT(C17,"MMM")) -> OCT | C17: 45230 | D17: 90 | E17: Bogotá - Belencito | F17: TURISTREN | G17: 01/10/2023 - 31/10/2023 | H17: USO DE VÍA PASAJEROS | J17: 36570 | K17: 850.96 | L17: =J17*K17 -> 31119607 | N17: =L17-M17 -> 31119607 | O17: =ROUND(N17*0.004,0) -> 124478 | P17: =(N17-O17) -> 30995129 | Q17: =P17 -> 30995129 | R17: 2023 | S17: =UPPER(TEXT(T17,"MMM")) -> NOV | T17: 45260 | U17: =+P17-Q17 -> 0
A18: =+YEAR(C18) -> 2023 | B18: =UPPER(TEXT(C18,"MMM")) -> OCT | C18: 45230 | D18: OC005 | E18: Bogotá - Belencito | F18: CTSA-INGERAL | G18: 01/10/2023 - 31/10/2023 | H18: USO DE VÍA CARGA | I18: 802914 | K18: 8 | L18: 6423314.1 | N18: =L18-M18 -> 6423314.1 | O18: =ROUND(N18*0.004,0) -> 25693 | P18: =(N18-O18) -> 6397621.1 | Q18: =P18 -> 6397621.1 | R18: 2023 | S18: =UPPER(TEXT(T18,"MMM")) -> NOV | T18: 45260 | U18: =+P18-Q18 -> 0
A19: =+YEAR(C19) -> 2023 | B19: =UPPER(TEXT(C19,"MMM")) -> NOV | C19: 45260 | D19: OC006 | E19: Bogotá - Belencito | F19: CTSA-INGERAL | G19: 01/11/2023 - 30/11/2023 | H19: USO DE VÍA CARGA | I19: 815841 | K19: 8 | L19: 6526731 | N19: =L19-M19 -> 6526731 | O19: =ROUND(N19*0.004,0) -> 26107 | P19: =(N19-O19) -> 6500624 | Q19: =P19 -> 6500624 | R19: 2024 | S19: =UPPER(TEXT(T19,"MMM")) -> ENE | T19: 45322 | U19: =+P19-Q19 -> 0
A20: 2023 | B20: =UPPER(TEXT(C20,"MMM")) -> NOV | C20: 45260 | D20: 107 | E20: Bogotá - Belencito | F20: TURISTREN | G20: 01/11/2023 - 30/11/2023 | H20: USO VIA PASAJEROS | J20: 35066 | K20: 850.96 | L20: 29839763 | N20: =L20-M20 -> 29839763 | O20: =ROUND(N20*0.004,0) -> 119359 | P20: =(N20-O20) -> 29720404 | Q20: =P20 -> 29720404 | R20: 2024 | S20: =UPPER(TEXT(T20,"MMM")) -> ENE | T20: 45322 | U20: =+P20-Q20 -> 0
A21: 2023 | B21: =UPPER(TEXT(C21,"MMM")) -> DIC | C21: 45280 | D21: 118 | E21: Bogotá - Belencito | F21: ACERIAS PAZ DEL RIO | G21: 45250 | H21: TREN ESPECIAL | J21: 514 | K21: 850.96 | L21: =J21*K21 -> 437393.44 | N21: =L21-M21 -> 437393.44 | O21: =ROUND(N21*0.004,0) -> 1750 | P21: =(N21-O21) -> 435643.44 | Q21: 435643.44 | R21: 2024 | S21: =UPPER(TEXT(T21,"MMM")) -> FEB | T21: 45348 | U21: =+P21-Q21 -> 0
A22: 2023 | B22: =UPPER(TEXT(C22,"MMM")) -> DIC | C22: 45290 | D22: 128 | E22: Bogotá - Belencito | F22: TURISTREN | G22: 01/12/2023 - 30/12/2023 | H22: USO VIA PASAJEROS | J22: 44115 | K22: 850.96 | L22: =J22*K22 -> 37540100 | N22: =L22-M22 -> 37540100 | O22: =ROUND(N22*0.004,0) -> 150160 | P22: =(N22-O22) -> 37389940 | Q22: =P22 -> 37389940 | R22: 2024 | S22: =UPPER(TEXT(T22,"MMM")) -> ENE | T22: 45322 | U22: =+P22-Q22 -> 0
A23: 2023 | B23: =UPPER(TEXT(C23,"MMM")) -> DIC | C23: 45290 | D23: OC007 | E23: Bogotá - Belencito | F23: CTSA-INGERAL | G23: 01/12/2023 - 31/12/2023 | H23: USO DE VÍA CARGA | I23: 856208 | K23: 8 | L23: 6849667 | N23: =L23-M23 -> 6849667 | O23: =ROUND(N23*0.004,0) -> 27399 | P23: =(N23-O23) -> 6822268 | Q23: =P23 -> 6822268 | R23: 2024 | S23: =UPPER(TEXT(T23,"MMM")) -> ENE | T23: 45322 | U23: =+P23-Q23 -> 0
A24: 2024 | B24: =UPPER(TEXT(C24,"MMM")) -> ENE | C24: 45322 | D24: 0C008 | E24: Bogotá - Belencito | F24: CTSA-INGERAL | G24: 01/1/2024 - 31/1/2024 | H24: USO DE VÍA CARGA | I24: 806159 | K24: =8*1.0928 -> 8.7424 | L24: 7047765 | N24: =L24-M24 -> 7047765 | O24: =ROUND(N24*0.004,0) -> 28191 | P24: =(N24-O24) -> 7019574 | Q24: 7019574 | R24: 2024 | S24: =UPPER(TEXT(T24,"MMM")) -> FEB | T24: 45348 | U24: =+P24-Q24 -> 0
A25: 2024 | B25: =UPPER(TEXT(C25,"MMM")) -> ENE | C25: 45322 | D25: 142 | E25: Bogotá - Belencito | F25: TURISTREN | G25: 01/1/2024 - 31/1/2024 | H25: USO VIA PASAJEROS | J25: 23406 | K25: =850.96*1.0928 -> 929.92909 | L25: 21765942 | N25: =L25-M25 -> 21765942 | O25: =ROUND(N25*0.004,0) -> 87064 | P25: =(N25-O25) -> 21678878 | Q25: 21678878 | R25: 2024 | S25: =UPPER(TEXT(T25,"MMM")) -> FEB | T25: 45348 | U25: =+P25-Q25 -> 0
A26: 2024 | B26: =UPPER(TEXT(C26,"MMM")) -> FEB | C26: 45351 | D26: OC009 | E26: Bogotá - Belencito | F26: CTSA-INGERAL | G26: 01/02/2024 - 29/02/2024 | H26: USO DE VÍA CARGA | I26: 1243965 | K26: =8*1.0928 -> 8.7424 | L26: 10875237 | N26: =L26-M26 -> 10875237 | O26: =ROUND(N26*0.004,0) -> 43501 | P26: =(N26-O26) -> 10831736 | Q26: 10831736 | R26: 2024 | S26: =UPPER(TEXT(T26,"MMM")) -> ABR | T26: 45383 | U26: =+P26-Q26 -> 0
A27: 2024 | B27: =UPPER(TEXT(C27,"MMM")) -> FEB | C27: 45351 | D27: OC009 | E27: Bogotá - Belencito | F27: CTSA-INGERAL | G27: 01/02/2024 - 29/02/2024 | H27: USO DE VÍA CARGA | P27: 0.19 | Q27: 0.19 | R27: 2024 | S27: =UPPER(TEXT(T27,"MMM")) -> ABR | T27: 45412 | U27: =+P27-Q27 -> 0
A28: 2024 | B28: =UPPER(TEXT(C28,"MMM")) -> FEB | C28: 45351 | D28: 160 | E28: Bogotá - Belencito | F28: TURISTREN | G28: 01/02/2024 - 29/02/2024 | H28: USO VIA PASAJEROS | J28: 34356 | K28: =850.96*1.0928 -> 929.92909 | L28: 31948675 | N28: =L28-M28 -> 31948675 | O28: =ROUND(N28*0.004,0) -> 127795 | P28: =(N28-O28) -> 31820880 | Q28: 31820880 | R28: 2024 | S28: =UPPER(TEXT(T28,"MMM")) -> ABR | T28: 45412 | U28: =+P28-Q28 -> 0
A29: 2024 | B29: =UPPER(TEXT(C29,"MMM")) -> MAR | C29: 45382 | D29: OC010 | E29: Bogotá - Belencito | F29: CTSA-INGERAL | G29: 01/03/2024 - 31/03/2024 | H29: USO DE VÍA CARGA | I29: 1217128 | K29: =8*1.0928 -> 8.7424 | L29: 10640620 | N29: =L29-M29 -> 10640620 | O29: =ROUND(N29*0.004,0) -> 42562 | P29: =(N29-O29) -> 10598058 | Q29: 10598058 | R29: 2024 | S29: =UPPER(TEXT(T29,"MMM")) -> ABR | T29: 45412 | U29: =+P29-Q29 -> 0
A30: 2024 | B30: =UPPER(TEXT(C30,"MMM")) -> MAR | C30: 45382 | D30: 177 | E30: Bogotá - Belencito | F30: TURISTREN | G30: 01/03/2024 - 31/03/2024 | H30: USO VIA PASAJEROS | J30: 43418 | K30: =850.96*1.0928 -> 929.92909 | L30: 40375701 | N30: 40375701 | O30: =ROUND(N30*0.004,0) -> 161503 | P30: =(N30-O30) -> 40214198 | Q30: =P30 -> 40214198 | R30: 2024 | S30: =UPPER(TEXT(T30,"MMM")) -> MAY | T30: 45440 | U30: =+P30-Q30 -> 0
A31: 2024 | B31: =UPPER(TEXT(C31,"MMM")) -> ABR | C31: 45412 | D31: OC011 | E31: Bogotá - Belencito | F31: CTSA-INGERAL | G31: 01/04/2024 - 30/04/2024 | H31: USO DE VÍA CARGA | I31: 1619942.2 | K31: 8.74 | L31: 14162182 | N31: 14162182 | O31: =ROUND(N31*0.004,0) -> 56649 | P31: =(N31-O31) -> 14105533 | Q31: =P31 -> 14105533 | R31: 2024 | S31: =UPPER(TEXT(T31,"MMM")) -> MAY | T31: 45440 | U31: =+P31-Q31 -> 0
A32: 2024 | B32: =UPPER(TEXT(C32,"MMM")) -> ABR | C32: 45412 | D32: 201 | E32: Bogotá - Belencito | F32: TURISTREN | G32: 01/04/2024 - 30/04/2024 | H32: USO DE VÍA PASAJEROS | J32: 35262 | K32: =850.96*1.0928 -> 929.92909 | L32: 32791192 | N32: 32791192 | O32: =ROUND(N32*0.004,0) -> 131165 | P32: =(N32-O32) -> 32660027 | Q32: =P32 -> 32660027 | R32: 2024 | S32: =UPPER(TEXT(T32,"MMM")) -> MAY | T32: 45440 | U32: =+P32-Q32 -> 0
A33: 2024 | B33: =UPPER(TEXT(C33,"MMM")) -> MAY | C33: 45443 | D33: OC012 | E33: Bogotá - Belencito | F33: CTSA-INGERAL | G33: 01/05/2024 - 31/05/2024 | H33: USO DE VÍA CARGA | I33: 1218151 | K33: 8.74 | L33: 10649561 | N33: 10649561 | O33: =ROUND(N33*0.004,0) -> 42598 | P33: =(N33-O33) -> 10606963 | Q33: 10606963 | R33: 2024 | S33: =UPPER(TEXT(T33,"MMM")) -> JUN | T33: 45469 | U33: =+P33-Q33 -> 0
A34: 2024 | B34: =UPPER(TEXT(C34,"MMM")) -> MAY | C34: 45443 | D34: 215 | E34: Bogotá - Belencito | F34: TURISTREN | G34: 01/05/2024 - 31/05/2024 | H34: USO DE VÍA PASAJEROS | J34: 32964 | K34: =850.96*1.0928 -> 929.92909 | L34: 30654213 | N34: 30654213 | O34: =ROUND(N34*0.004,0) -> 122617 | P34: =(N34-O34) -> 30531596 | Q34: 30531596 | R34: 2024 | S34: =UPPER(TEXT(T34,"MMM")) -> JUN | T34: 45469 | U34: =+P34-Q34 -> 0
A35: 2024 | B35: =UPPER(TEXT(C35,"MMM")) -> JUN | C35: 45473 | D35: OC013 | E35: Bogotá - Belencito | F35: CTSA-INGERAL | G35: 01/06/2024 - 30/06/2024 | H35: USO DE VÍA CARGA | I35: 1319475 | K35: 8.74 | L35: 11535378 | N35: =L35 -> 11535378 | O35: =ROUND(N35*0.004,0) -> 46142 | P35: 11489236 | Q35: 11489236 | R35: 2024 | S35: =UPPER(TEXT(T35,"MMM")) -> JUL | T35: 45504 | U35: =+P35-Q35 -> 0
A36: 2024 | B36: =UPPER(TEXT(C36,"MMM")) -> JUN | C36: 45473 | D36: 237 | E36: Bogotá - Belencito | F36: TURISTREN | G36: 01/06/2024 - 30/06/2024 | H36: USO DE VÍA PASAJEROS | J36: 19428 | K36: =850.96*1.0928 -> 929.92909 | L36: 18066680 | N36: =L36 -> 18066680 | O36: =ROUND(N36*0.004,0) -> 72267 | P36: =(N36-O36) -> 17994413 | Q36: 17994413 | R36: 2024 | S36: =UPPER(TEXT(T36,"MMM")) -> JUL | T36: 45504 | U36: =+P36-Q36 -> 0
A37: 2024 | B37: =UPPER(TEXT(C37,"MMM")) -> JUL | C37: 45504 | D37: OC014 | E37: Bogotá - Belencito | F37: CTSA-INGERAL | G37: 01/07/2024 - 31/07/2024 | H37: USO DE VÍA CARGA | I37: 1341466.9 | K37: 8.74 | L37: 11727640 | N37: 11727640 | O37: =ROUND(N37*0.004,0) -> 46911 | P37: =(N37-O37) -> 11680729 | Q37: =P37 -> 11680729 | R37: 2024 | S37: =UPPER(TEXT(T37,"MMM")) -> AGO | T37: 45533 | U37: =+P37-Q37 -> 0
A38: 2024 | B38: =UPPER(TEXT(C38,"MMM")) -> JUL | C38: 45504 | D38: 247 | E38: Bogotá - Belencito | F38: TURISTREN | G38: 01/07/2024 - 31/07/2024 | H38: USO DE VÍA PASAJEROS | J38: 26264 | K38: =850.96*1.0928 -> 929.92909 | L38: 24423682 | N38: 24423682 | O38: =ROUND(N38*0.004,0) -> 97695 | P38: =(N38-O38) -> 24325987 | Q38: 24325987 | R38: 2024 | S38: =UPPER(TEXT(T38,"MMM")) -> SEP | T38: 45565 | U38: =+P38-Q38 -> 0
A39: 2024 | B39: =UPPER(TEXT(C39,"MMM")) -> AGO | C39: 45535 | D39: OC015 | E39: Bogotá - Belencito | F39: CTSA-INGERAL | G39: 01/08/2024 - 31/08/2024 | H39: USO DE VÍA CARGA | I39: 1068577.4 | K39: 8.74 | L39: 9341931.2 | N39: =L39 -> 9341931.2 | O39: =ROUND(N39*0.004,0) -> 37368 | P39: =(N39-O39) -> 9304563.2 | Q39: 9304563.2 | R39: 2024 | S39: =UPPER(TEXT(T39,"MMM")) -> SEP | T39: 45565 | U39: =+P39-Q39 -> 0
A40: 2024 | B40: =UPPER(TEXT(C40,"MMM")) -> AGO | C40: 45535 | D40: 267 | E40: Bogotá - Belencito | F40: TURISTREN | G40: 01/08/2024 - 31/08/2024 | H40: USO DE VÍA PASAJEROS | J40: 43540 | K40: =850.96*1.0928 -> 929.92909 | L40: 40489152 | N40: =L40 -> 40489152 | O40: =ROUND(N40*0.004,0) -> 161957 | P40: =(N40-O40) -> 40327195 | Q40: 40327195 | R40: 2024 | S40: =UPPER(TEXT(T40,"MMM")) -> NOV | T40: 45623 | U40: =+P40-Q40 -> 0
...

Sheet Material rodante base
F2: Material rodante
A3: Etiquetas de fila | B3: Suma de Valor a Consignar a la ANI | C3: Suma de Valor Pagado | F3: Etiquetas de fila | G3: Suma de Valor Pagado
A4: 2023 | B4: 1.0680164e+08 | C4: 1.0680164e+08 | F4: 2023 | G4: 1.0680164e+08
A5: Consorcio CTSA-INGERAL | B5: 1.0680164e+08 | C5: 1.0680164e+08 | F5: JUN | G5: 14759305
A6: 2024 | B6: 1.8635279e+08 | C6: 1.5170825e+08 | F6: JUL | G6: 18449131
A7: Consorcio CTSA-INGERAL | B7: 1.8635279e+08 | C7: 1.5170825e+08 | F7: AGO | G7: 14759305
A8: 2025 | B8: 19178664 | F8: SEP | G8: 16604217
A9: Consorcio CTSA-INGERAL | B9: 19178664 | F9: OCT | G9: 14759305
A10: Total general | B10: 3.123331e+08 | C10: 2.5850989e+08 | F10: NOV | G10: 15150166
F11: DIC | G11: 12320214
F12: 2024 | G12: 1.5170825e+08
F13: ENE | G13: 16813221
F14: FEB | G14: 14389891
F15: MAR | G15: 11655292
F16: ABR | G16: 14805698
F17: MAY | G17: 13178594
F18: JUN | G18: 13812201
F19: JUL | G19: 14322432
F20: AGO | G20: 18432270
F21: SEP | G21: 17979918
F22: OCT | G22: 16318729
F23: NOV
F24: DIC
F25: 2025
F26: ENE
F27: Total general | G27: 2.5850989e+08

Sheet Uso de vía
A3: Etiquetas de fila | B3: Suma de Valor Pagado
A4: ENE | B4: 80433237
A5: 2024 | B5: 80433237
A6: FEB | B6: 29134095
A7: 2024 | B7: 29134095
A8: ABR | B8: 53250675
A9: 2024 | B9: 53250675
A10: MAY | B10: 86979758
A11: 2024 | B11: 86979758
A12: JUN | B12: 87681256
A13: 2023 | B13: 46542698
A14: 2024 | B14: 41138558
A15: JUL | B15: 96929029
A16: 2023 | B16: 67445380
A17: 2024 | B17: 29483649
A18: AGO | B18: 42648474
A19: 2023 | B19: 30967745
A20: 2024 | B20: 11680729
A21: SEP | B21: 33630550
A22: 2024 | B22: 33630550
A23: OCT | B23: 79005069
A24: 2023 | B24: 34846424
A25: 2024 | B25: 44158645
A26: NOV | B26: 1.3096301e+08
A27: 2023 | B27: 79024150
A28: 2024 | B28: 51938861
A29: Total general | B29: 7.2065515e+08

Sheet Materal rodante
A1: Año | B1: Mes | C1: Fecha | D1: # Factura | E1: Corredor | F1: Tercero | G1: Periodo | H1: Concepto | I1: # Toneladas | J1: Valor Facturado | K1: IVA | L1: Valor bruto | M1: 4 X 1000 | N1: Valor a Consignar a la ANI | O1: Valor consignado | P1: Valor Pagado | Q1: Año2 | R1: Mes3 | S1: Fecha4 | T1: Valor Por Cobrar
A2: =+YEAR(C2) -> 2023 | B2: =UPPER(TEXT(C2,"MMM")) -> JUN | C2: 45107 | D2: OC001 | E2: Bogotá - Belencito | F2: Consorcio CTSA-INGERAL | G2: 01/06/2023 - 30/06/2023 | H2: Arriendo material rodante informe OC001 | I2: 3117 | J2: 17634109 | K2: 2815530 | L2: 14818579 | M2: =ROUND(L2*0.004,0) -> 59274 | N2: 14759305 | O2: 14759305 | P2: 14759305 | Q2: =+YEAR(S2) -> 2023 | R2: =+MONTH(S2) -> 7 | S2: 45135 | T2: =N2-P2 -> 0
A3: =+YEAR(C3) -> 2023 | B3: =UPPER(TEXT(C3,"MMM")) -> JUL | C3: 45138 | D3: OC002 | E3: Bogotá - Belencito | F3: Consorcio CTSA-INGERAL | G3: 01/07/2023 - 30/07/2023 | H3: Arriendo material rodante informe OC002 | I3: 3905 | J3: 22042636 | K3: 3519412 | L3: 18523224 | M3: =ROUND(L3*0.004,0) -> 74093 | N3: =L3-M3 -> 18449131 | O3: 9224564 | P3: 9224564 | Q3: =+YEAR(S3) -> 2023 | R3: =+MONTH(S3) -> 7 | S3: 45135 | T3: =N3-P3 -> 9224567
A4: =+YEAR(C4) -> 2023 | B4: =UPPER(TEXT(C4,"MMM")) -> JUL | C4: 45138 | D4: OC002 | E4: Bogotá - Belencito | F4: Consorcio CTSA-INGERAL | G4: 01/07/2023 - 30/07/2023 | H4: Arriendo material rodante informe OC002 | J4: 0 | K4: 0 | L4: 0 | M4: =ROUND(L4*0.004,0) -> 0 | N4: =L4-M4 -> 0 | O4: 9224567 | P4: 9224567 | Q4: =+YEAR(S4) -> 2023 | R4: =+MONTH(S4) -> 8 | S4: 45142 | T4: =N4-P4 -> -9224567
A5: =+YEAR(C5) -> 2023 | B5: =UPPER(TEXT(C5,"MMM")) -> AGO | C5: 45169 | D5: OC003 | E5: Bogotá - Belencito | F5: Consorcio CTSA-INGERAL | G5: 01/08/2023 - 30/08/2023 | H5: Arriendo material rodante informe OC003 | I5: 3119 | J5: 17634109 | K5: 2815130 | L5: 14818579 | M5: =ROUND(L5*0.004,0) -> 59274 | N5: =L5-M5 -> 14759305 | O5: 9224564 | P5: 9224564 | Q5: =+YEAR(S5) -> 2023 | R5: =+MONTH(S5) -> 8 | S5: 45142 | T5: =N5-P5 -> 5534741
A6: =+YEAR(C6) -> 2023 | B6: =UPPER(TEXT(C6,"MMM")) -> AGO | C6: 45169 | D6: OC003 | E6: Bogotá - Belencito | F6: Consorcio CTSA-INGERAL | G6: 01/08/2023 - 30/08/2023 | H6: Arriendo material rodante informe OC003 | O6: 5534741 | P6: 5534741 | Q6: =+YEAR(S6) -> 2023 | R6: 11 | S6: 45233 | T6: =N6-P6 -> -5534741
A7: =+YEAR(C7) -> 2023 | B7: =UPPER(TEXT(C7,"MMM")) -> SEP | C7: 45199 | D7: OC004 | E7: Bogotá - Belencito | F7: Consorcio CTSA-INGERAL | G7: 01/092023 - 30/09/2023 | H7: Arriendo material rodante informe OC004 | I7: 3508 | J7: 19838372 | K7: 3167471 | L7: 16670901 | M7: =ROUND(L7*0.004,0) -> 66684 | N7: =L7-M7 -> 16604217 | O7: 16604217 | P7: 16604217 | Q7: =+YEAR(S7) -> 2023 | R7: 11 | S7: 45233 | T7: =N7-P7 -> 0
A8: =+YEAR(C8) -> 2023 | B8: =UPPER(TEXT(C8,"MMM")) -> OCT | C8: 45230 | D8: OC005 | E8: Bogotá - Belencito | F8: Consorcio CTSA-INGERAL | G8: 01/10/2023 - 30/10/2023 | H8: Arriendo material rodante informe OC005 | I8: 3124 | J8: 17634109 | K8: 2815530 | L8: 14818579 | M8: =ROUND(L8*0.004,0) -> 59274 | N8: =L8-M8 -> 14759305 | O8: =N8 -> 14759305 | P8: =O8 -> 14759305 | Q8: =+YEAR(S8) -> 2023 | R8: 11 | S8: 45260 | T8: =N8-P8 -> 0
A9: 2023 | B9: =UPPER(TEXT(C9,"MMM")) -> NOV | C9: 45260 | D9: OC006 | E9: Bogotá - Belencito | F9: Consorcio CTSA-INGERAL | G9: 01/11/2023 - 30/11/2023 | H9: Arriendo material rodante informe OC006 | I9: 3174 | J9: 18101102 | K9: 2890092 | L9: 15211010 | M9: =ROUND(L9*0.004,0) -> 60844 | N9: =L9-M9 -> 15150166 | O9: =N9 -> 15150166 | P9: =O9 -> 15150166 | Q9: 2024 | R9: 1 | S9: 45322 | T9: =N9-P9 -> 0
A10: 2023 | B10: =UPPER(TEXT(C10,"MMM")) -> DIC | C10: 45291 | D10: OC007 | E10: Bogotá - Belencito | F10: Consorcio CTSA-INGERAL | G10: 01/12/2023 - 30/12/2023 | H10: Arriendo material rodante informe OC007 | I10: 3332 | J10: 14720054 | K10: 2350361 | L10: =J10-K10 -> 12369693 | M10: =ROUND(L10*0.004,0) -> 49479 | N10: =L10-M10 -> 12320214 | O10: =N10 -> 12320214 | P10: =O10 -> 12320214 | Q10: 2024 | R10: 1 | S10: 45322 | T10: =N10-P10 -> 0
A11: 2024 | B11: =UPPER(TEXT(C11,"MMM")) -> ENE | C11: 45322 | D11: OC008 | E11: Bogotá - Belencito | F11: Consorcio CTSA-INGERAL | G11: 01/1/2024 - 30/1/2024 | H11: Arriendo material rodante informe OC008 | I11: 3415.66 | J11: 20088086 | K11: 3207341 | L11: 16880744 | M11: =ROUND(L11*0.004,0) -> 67523 | N11: =L11-M11 -> 16813221 | O11: =N11 -> 16813221 | P11: =O11 -> 16813221 | Q11: 2024 | R11: 2 | S11: 45348 | T11: =N11-P11 -> 0
A12: 2024 | B12: =UPPER(TEXT(C12,"MMM")) -> FEB | C12: 45351 | D12: OC009 | E12: Bogotá - Belencito | F12: Consorcio CTSA-INGERAL | G12: 01/2/2024 - 29/2/2024 | H12: Arriendo material rodante informe OC009 | I12: 5200.31 | J12: 17192742 | K12: 2745060 | L12: 14447682 | M12: =ROUND(L12*0.004,0) -> 57791 | N12: =L12-M12 -> 14389891 | O12: 14389891 | P12: 14389891 | Q12: 2024 | R12: 4 | S12: 45383 | T12: =N12-P12 -> 0
A13: 2024 | B13: =UPPER(TEXT(C13,"MMM")) -> MAR | C13: 45382 | D13: OC010 | E13: Bogotá - Belencito | F13: Consorcio CTSA-INGERAL | G13: 01/3/2024 - 31/3/2024 | H13: Arriendo material rodante informe OC010 | I13: 5074.38 | J13: 13925499 | K13: 2223399 | L13: 11702100 | M13: =ROUND(L13*0.004,0) -> 46808 | N13: =L13-M13 -> 11655292 | O13: 11655292 | P13: 11655292 | Q13: 2024 | R13: 4 | S13: 45412 | T13: =N13-P13 -> 0
A14: 2024 | B14: =UPPER(TEXT(C14,"MMM")) -> ABR | C14: 45412 | D14: OC011 | E14: Bogotá - Belencito | F14: Consorcio CTSA-INGERAL | G14: 01/4/2024 - 30/4/2024 | H14: Arriendo material rodante informe OC011 | I14: 6888.5 | J14: 17689540 | K14: 2824830.3 | L14: 14865159 | M14: =ROUND(L14*0.004,0) -> 59461 | N14: =L14-M14 -> 14805698 | O14: =N14 -> 14805698 | P14: =O14 -> 14805698 | Q14: 2024 | R14: 5 | S14: 45440 | T14: =N14-P14 -> 0
A15: 2024 | B15: =UPPER(TEXT(C15,"MMM")) -> MAY | C15: 45443 | D15: OC012 | E15: Bogotá - Belencito | F15: Consorcio CTSA-INGERAL | G15: 01/5/2024 - 31/5/2024 | H15: Arriendo material rodante informe OC012 | I15: 5026.58 | J15: 15745509 | K15: 2513988.9 | L15: 13231520 | M15: =ROUND(L15*0.004,0) -> 52926 | N15: =L15-M15 -> 13178594 | O15: 13178594 | P15: 13178594 | Q15: 2024 | R15: 6 | S15: 45469 | T15: =N15-P15 -> 0
A16: 2024 | B16: =UPPER(TEXT(C16,"MMM")) -> JUN | C16: 45473 | D16: OC013 | E16: Bogotá - Belencito | F16: Consorcio CTSA-INGERAL | G16: 01/6/2024 - 30/6/2024 | H16: Arriendo material rodante informe OC013 | I16: 5474.64 | J16: 16502529 | K16: 2634857.6 | L16: 13867672 | M16: =ROUND(L16*0.004,0) -> 55471 | N16: =L16-M16 -> 13812201 | O16: 13812201 | P16: =N16 -> 13812201 | Q16: 2024 | R16: 7 | S16: 45504 | T16: =N16-P16 -> 0
A17: 2024 | B17: =UPPER(TEXT(C17,"MMM")) -> JUL | C17: 45504 | D17: OC014 | E17: Bogotá - Belencito | F17: Consorcio CTSA-INGERAL | G17: 01/7/2024 - 31/7/2024 | H17: Arriendo material rodante informe OC014 | I17: 5660.16 | J17: 17043694 | K17: 2721262.1 | L17: 14322432 | M17: =ROUND(L17*0.004,0) -> 57290 | N17: 14322432 | O17: 14322432 | P17: =N17 -> 14322432 | Q17: 2024 | R17: 8 | S17: 45533 | T17: =N17-P17 -> 0
A18: 2024 | B18: =UPPER(TEXT(C18,"MMM")) -> AGO | C18: 45535 | D18: OC015 | E18: Bogotá - Belencito | F18: Consorcio CTSA-INGERAL | G18: 01/8/2024 - 31/8/2024 | H18: Arriendo material rodante informe OC015 | I18: 4295.28 | J18: 22022491 | K18: 3516196 | L18: 18506295 | M18: =ROUND(L18*0.004,0) -> 74025 | N18: =L18-M18 -> 18432270 | O18: 18432270 | P18: 18432270 | Q18: 2024 | R18: 9 | S18: 45565 | T18: =N18-P18 -> 0
A19: 2024 | B19: =UPPER(TEXT(C19,"MMM")) -> SEP | C19: 45565 | D19: OC016 | E19: Bogotá - Belencito | F19: Consorcio CTSA-INGERAL | G19: 01/9/2024 - 30/9/2024 | H19: Arriendo material rodante informe OC016 | I19: 5451.34 | J19: 21482032 | K19: 3429904.2 | L19: 18052127 | M19: =ROUND(L19*0.004,0) -> 72209 | N19: =L19-M19 -> 17979918 | O19: 17979918 | P19: 17979918 | Q19: 2024 | R19: 10 | S19: 45596 | T19: =N19-P19 -> 0
A20: 2024 | B20: =UPPER(TEXT(C20,"MMM")) -> OCT | C20: 45596 | D20: OC017 | E20: Bogotá - Belencito | F20: Consorcio CTSA-INGERAL | G20: 01/10/2024 - 31/10/2024 | H20: Arriendo material rodante informe OC017 | I20: 5365.159 | J20: 19497277 | K20: 3113010.6 | L20: 16384266 | M20: =ROUND(L20*0.004,0) -> 65537 | N20: =L20-M20 -> 16318729 | O20: 16318729 | P20: 16318729 | Q20: 2024 | R20: 11 | S20: 45623 | T20: =N20-P20 -> 0
A21: 2024 | B21: =UPPER(TEXT(C21,"MMM")) -> NOV | C21: 45626 | D21: OC018 | E21: Bogotá - Belencito | F21: Consorcio CTSA-INGERAL | G21: 01/11/2024 - 30/11/2024 | H21: Arriendo material rodante informe OC018 | I21: 2827.26 | J21: 22599152 | K21: 3608268 | L21: 18990884 | M21: =ROUND(L21*0.004,0) -> 75964 | N21: =L21-M21 -> 18914920 | O21: 18914920 | P21: 18914920 | Q21: 2025 | R21: 2 | S21: 45714 | T21: =N21-P21 -> 0
A22: 2024 | B22: =UPPER(TEXT(C22,"MMM")) -> DIC | C22: 45657 | D22: OC019 | E22: Bogotá - Belencito | F22: Consorcio CTSA-INGERAL | G22: 01/12/2024 - 31/12/2024 | H22: Arriendo material rodante informe OC019 | I22: 3153.53 | J22: 18793426 | K22: 3000631 | L22: 15792795 | M22: =ROUND(L22*0.004,0) -> 63171 | N22: =L22-M22 -> 15729624 | O22: 15729624 | P22: =Tabla2[[#This Row],[Valor a Consignar a la ANI]] -> 15729624 | Q22: 2025 | R22: 4 | S22: 45770 | T22: =N22-P22 -> 0
A23: 2025 | B23: =UPPER(TEXT(C23,"MMM")) -> ENE | C23: 45688 | D23: OC020 | E23: Bogotá - Belencito | F23: Consorcio CTSA-INGERAL | G23: 01/1/2025 - 31/1/2025 | H23: Arriendo material rodante informe OC020 | I23: 2693.64 | J23: 22914268 | K23: =J23-J23/1.19 -> 3658580.5 | L23: =J23-K23 -> 19255687 | M23: =ROUND(L23*0.004,0) -> 77023 | N23: =L23-M23 -> 19178664 | O23: =Tabla2[[#This Row],[Valor a Consignar a la ANI]] -> 19178664 | P23: =Tabla2[[#This Row],[Valor consignado]] -> 19178664 | Q23: 2025 | R23: 7 | S23: 45845 | T23: =N23-P23 -> 0
A24: 2025 | B24: =UPPER(TEXT(C24,"MMM")) -> FEB | C24: 45716 | D24: OC021 | E24: Bogotá - Belencito | F24: Consorcio CTSA-INGERAL | G24: 01/2/2025 - 28/2/2025 | H24: Arriendo material rodante informe OC021 | I24: 3918.32 | J24: 21676517 | K24: =J24-J24/1.19 -> 3460956.5 | L24: =J24-K24 -> 18215561 | M24: =ROUND(L24*0.004,0) -> 72862 | N24: =L24-M24 -> 18142699 | O24: =Tabla2[[#This Row],[Valor a Consignar a la ANI]] -> 18142699 | P24: =Tabla2[[#This Row],[Valor consignado]] -> 18142699 | Q24: 2025 | R24: 8 | S24: 45873 | T24: =N24-P24 -> 0
A25: 2025 | B25: =UPPER(TEXT(C25,"MMM")) -> MAR | C25: 45747 | D25: OC022 | E25: Bogotá - Belencito | F25: Consorcio CTSA-INGERAL | G25: 01/3/2025 - 31/3/2025 | H25: Arriendo material rodante informe OC022 | I25: 3878.57 | J25: 25340779 | K25: 4046006.7 | L25: =J25-K25 -> 21294772 | M25: =ROUND(L25*0.004,0) -> 85179 | N25: =L25-M25 -> 21209593 | O25: 21209593 | P25: 21209593 | Q25: 2025 | R25: 9 | S25: 45904 | T25: =N25-P25 -> 0
A26: 2025 | B26: =UPPER(TEXT(C26,"MMM")) -> ABR | C26: 45777 | D26: OC023 | E26: Bogotá - Belencito | F26: Consorcio CTSA-INGERAL | G26: 01/4/2025 - 30/4/2025 | H26: Arriendo material rodante informe OC023 | I26: 3101.91 | J26: 20272623 | K26: 3236805.4 | L26: =J26-K26 -> 17035818 | M26: =ROUND(L26*0.004,0) -> 68143 | N26: =L26-M26 -> 16967675 | O26: 16767675 | P26: 16967675 | Q26: 2025 | R26: 10 | S26: 45932 | T26: =N26-P26 -> 0
A27: 2025 | B27: =UPPER(TEXT(C27,"MMM")) -> MAY | C27: 45808 | D27: OC024 | E27: Bogotá - Belencito | F27: Consorcio CTSA-INGERAL | G27: 01/5/2025 - 31/5/2025 | H27: Arriendo material rodante informe OC024 | I27: 4128.11 | J27: 26462981 | K27: 4225181.9 | L27: =J27-K27 -> 22237799 | M27: =ROUND(L27*0.004,0) -> 88951 | N27: =L27-M27 -> 22148848 | O27: 22148848 | P27: 22148848 | Q27: 2025 | R27: 10 | S27: 45938 | T27: =N27-P27 -> 0
A28: 2025 | B28: =UPPER(TEXT(C28,"MMM")) -> JUN | C28: 45838 | D28: OC025 | E28: Bogotá - Belencito | F28: Consorcio CTSA-INGERAL | G28: 01/6/2025 - 30/6/2025 | H28: Arriendo material rodante informe OC025 | I28: 8022 | J28: 14642721 | K28: 2337913.4 | L28: =J28-K28 -> 12304808 | M28: =ROUND(L28*0.004,0) -> 49219 | N28: =L28-M28 -> 12255589 | O28: 12255589 | P28: 12255589 | Q28: 2025 | R28: 10 | S28: 45961 | T28: =N28-P28 -> 0
A29: 2025 | B29: =UPPER(TEXT(C29,"MMM")) -> JUL | C29: 45869 | D29: OC026 | E29: Bogotá - Belencito | F29: Consorcio CTSA-INGERAL | G29: 01/7/2025 - 31/7/2025 | H29: Arriendo material rodante informe OC026 | I29: 8071.19 | J29: 14064109 | K29: 2245529.9 | L29: =J29-K29 -> 11818579 | M29: =ROUND(L29*0.004,0) -> 47274 | N29: =L29-M29 -> 11771305 | O29: 11771305 | P29: 11771305 | Q29: 2025 | R29: 10 | S29: 45961 | T29: =N29-P29 -> 0
A30: 2025 | B30: =UPPER(TEXT(C30,"MMM")) -> AGO | C30: 45900 | D30: OC027 | E30: Bogotá - Belencito | F30: Consorcio CTSA-INGERAL | G30: 01/8/2025 - 31/8/2025 | H30: Arriendo material rodante informe OC027 | I30: 9566.4 | J30: 14222747 | K30: 2270858.7 | L30: =J30-K30 -> 11951888 | M30: =ROUND(L30*0.004,0) -> 47808 | N30: =L30-M30 -> 11904080 | T30: =N30-P30 -> 11904080
A31: 2025 | B31: =UPPER(TEXT(C31,"MMM")) -> SEP | C31: 45930 | D31: OC028 | E31: Bogotá - Belencito | F31: Consorcio CTSA-INGERAL | G31: 01/9/2025 - 30/9/2025 | H31: Arriendo material rodante informe OC028 | I31: 4338.15 | J31: 17867713 | K31: 2852828.1 | L31: 15014885 | M31: =ROUND(L31*0.004,0) -> 60060 | N31: =L31-M31 -> 14954825 | T31: =N31-P31 -> 14954825
N32: =SUBTOTAL(109,Tabla2[Valor a Consignar a la ANI]) -> 4.4168771e+08 | P32: =SUBTOTAL(109,Tabla2[Valor Pagado]) -> 4.1482881e+08 | T32: =SUM(T2:T31) -> 26858905
N34: Usuario de vía | O34: Facturado por CTSA-INGERAL | P34: Recaudado por CTSA-INGERAL | Q34: Consignado a la ANI | R34: Pendiente por cobro | S34: Observación
N35: CTSA | O35: =N31 -> 14954825 | P35: =P25 -> 21209593 | Q35: =P25 -> 21209593 | R35: =+T26+T27+T28+T29+T30+T31 -> 26858905 | S35: 1. Los fondos aún por cobrar están asociados a las facturas, OC023 del mes de abril, OC024 del mes de mayo, OC025 del mes de junio de 2025, OC026 del mes de julio del 2025; OC027 del mes de agosto del 2025 y OC028 del mes de septiembre 2. El importe consignado a la ANI pertenece a la factura OC022 de marzo de 2025
N36: Total | O36: =SUM(O35) -> 14954825 | P36: =SUM(P35) -> 21209593 | Q36: =Q35 -> 21209593 | R36: =R35 -> 26858905

Sheet Operacion comercial 
C2: Operación Comercial
A7: Los valores aquí presentados pertenecen a los valores brutos.

Sheet Base de datos O.P
A1: N° Servicio | B1: Mes | C1: AÑO | D1: Configuración Tren | E1: Fecha Salida | F1: Fecha llegada | G1: Días | H1: Cantidad Locomotoras | I1: V/r Alquiler locomotoras | J1: Cantidad plataformas | K1: V/r Alquiler plataformas | L1: V/r Alquiler Mat. Rodante | M1: Toneladas Transportad. | N1: Km recorridos | O1: Ton-km | P1: V/r Importe Uso de Vía | Q1: Remisión No. | R1: Recorrido Locomotras Trabajando | S1: Cantidad Combustible Consumido | T1: V/r Combustible | U1: Factura | V1: Columna1
A2: 1 | B2: =UPPER((TEXT(Tabla3[[#This Row],[Fecha llegada]],"MMM"))) -> ENE | C2: =YEAR(Tabla3[[#This Row],[Fecha llegada]]) -> 2024 | D2: Loc. 1034-1001 Plat. 4083,4071,4095,4069,4061,4003,4060,4146, 4124,4120,4151,4104,4162,4159 | E2: 45297 | F2: 45298 | G2: 2 | H2: 2 | I2: 1303630.7 | J2: 14 | K2: 720587.18 | L2: 2024217.9 | M2: 388 | N2: 257 | O2: =M2*N2 -> 99716 | P2: 871757.16 | Q2: REMISION ARGOS RPSM-00299788 | R2: 614 | S2: 491.2 | T2: 4015324.2 | U2: OC008
A3: 2 | B3: =UPPER((TEXT(Tabla3[[#This Row],[Fecha llegada]],"MMM"))) -> ENE | C3: =YEAR(Tabla3[[#This Row],[Fecha llegada]]) -> 2024 | D3: Loc. 1034-1012 Plat. 4003,4100,4079,4087,4068,405,4031,4007, 4002,4072,4061,4060,4069,4010 | E3: 45301 | F3: 45302 | G3: 2 | H3: 2 | I3: 1303630.7 | J3: 14 | K3: 720587.18 | L3: 2024217.9 | M3: 390.78 | N3: 257 | O3: =M3*N3 -> 100430.46 | P3: 878003.25 | Q3: REMISION ARGOS RPSM-00299890 | R3: 614 | S3: 491.2 | T3: 4015324.2 | U3: OC008
A4: 3 | B4: =UPPER((TEXT(Tabla3[[#This Row],[Fecha llegada]],"MMM"))) -> ENE | C4: =YEAR(Tabla3[[#This Row],[Fecha llegada]]) -> 2024 | D4: Loc. 1034-1012 Plat. 4072,4061,4060,4048,4083,4071,4095,4073, 4010,4007,4002,4018,4102,4001 | E4: 45303 | F4: 45304 | G4: 2 | H4: 2 | I4: 1303630.7 | J4: 14 | K4: 720587.18 | L4: 2024217.9 | M4: 389.55 | N4: 257 | O4: =M4*N4 -> 100114.35 | P4: 875239.69 | Q4: REMISION ARGOS RPSM-00300031 | R4: 614 | S4: 491.2 | T4: 4015324.2 | U4: OC008
A5: 4 | B5: =UPPER((TEXT(Tabla3[[#This Row],[Fecha llegada]],"MMM"))) -> ENE | C5: =YEAR(Tabla3[[#This Row],[Fecha llegada]]) -> 2024 | D5: Loc. 1034-1012 Plat. 4071,4095,4003,4100,4079,4087,4001,4002, 4018,4102,4083,408,4053,4069 | E5: 45306 | F5: 45307 | G5: 2 | H5: 2 | I5: 1303630.7 | J5: 14 | K5: 720587.18 | L5: 2024217.9 | M5: 389.55 | N5: 257 | O5: =M5*N5 -> 100114.35 | P5: 875239.69 | Q5: REMISION ARGOS RPSM-00300173 | R5: 614 | S5: 491.2 | T5: 4015324.2 | U5: OC008
A6: 5 | B6: =UPPER((TEXT(Tabla3[[#This Row],[Fecha llegada]],"MMM"))) -> ENE | C6: =YEAR(Tabla3[[#This Row],[Fecha llegada]]) -> 2024 | D6: Loc. 1034-1012 Plat. 4071,4095,4087,,4001,4072,4061,4060,4048, 4073,4010,4007,4003,4079,4100 | E6: 45308 | F6: 45309 | G6: 2 | H6: 2 | I6: 1303630.7 | J6: 14 | K6: 720587.18 | L6: 2024217.9 | M6: 387.1 | N6: 257 | O6: =M6*N6 -> 99484.7 | P6: 869735.04 | Q6: REMISION ARGOS RPSM-00300352 | R6: 614 | S6: 491.2 | T6: 4015324.2 | U6: OC008
A7: 6 | B7: =UPPER((TEXT(Tabla3[[#This Row],[Fecha llegada]],"MMM"))) -> ENE | C7: =YEAR(Tabla3[[#This Row],[Fecha llegada]]) -> 2024 | D7: Loc. 1001 Plat. 4173,4159,4162,4104,4151,4146,4120,4124 | E7: 45314 | F7: 45315 | G7: 1 | H7: 1 | I7: 438442.96 | J7: 8 | K7: 248558.43 | L7: 687001.39 | M7: 300.8 | N7: 18.75 | O7: =M7*N7 -> 5640 | P7: 49307.136 | Q7: T1 01 | R7: 37.5 | S7: 30 | T7: 245235.6 | U7: OC008
A8: 7 | B8: =UPPER((TEXT(Tabla3[[#This Row],[Fecha llegada]],"MMM"))) -> ENE | C8: =YEAR(Tabla3[[#This Row],[Fecha llegada]]) -> 2024 | D8: Loc. 1044-1012 Plat. 4061,4060,40002,4018,4102,4083,4068,4053,4001,4003,4079,4103,4072,4069 | E8: 45315 | F8: 45316 | G8: 2 | H8: 2 | I8: 1303630.7 | J8: 14 | K8: 720587.18 | L8: 2024217.9 | M8: 389.55 | N8: 257 | O8: =M8*N8 -> 100114.35 | P8: 875239.69 | Q8: REMISION ARGOS RPSM-00300803 | R8: 614 | S8: 491.2 | T8: 4015324.2 | U8: OC008
A9: 8 | B9: =UPPER((TEXT(Tabla3[[#This Row],[Fecha llegada]],"MMM"))) -> ENE | C9: =YEAR(Tabla3[[#This Row],[Fecha llegada]]) -> 2024 | D9: Loc. 1044-1001 Plat. 4072,4102,4083,4068,4087,4048,4073,4010, 4007,4053,4071,4095,4061,4060 | E9: 45317 | F9: 45318 | G9: 2 | H9: 2 | I9: 1303630.7 | J9: 14 | K9: 720587.18 | L9: 2024217.9 | M9: 388.33 | N9: 257 | O9: =M9*N9 -> 99800.81 | P9: 872498.6 | Q9: REMISION ARGOS RPSM-00300992 | R9: 614 | S9: 491.2 | T9: 4015324.2 | U9: OC008
A10: 9 | B10: =UPPER((TEXT(Tabla3[[#This Row],[Fecha llegada]],"MMM"))) -> ENE | C10: =YEAR(Tabla3[[#This Row],[Fecha llegada]]) -> 2024 | D10: Loc. 1044-1001 Plat. 4053,4071,4095,4061,4002,4018,4003,4079, 4060,4072,4102,4083,4068,4103 | E10: 45320 | F10: 45321 | G10: 2 | H10: 2 | I10: 1303630.7 | J10: 14 | K10: 720587.18 | L10: 2024217.9 | M10: 392 | N10: 257 | O10: =M10*N10 -> 100744 | P10: 880744.35 | Q10: REMISION ARGOS RPSM-00301142 | R10: 614 | S10: 491.2 | T10: 4015324.2 | U10: OC008
A11: 10 | B11: =UPPER((TEXT(Tabla3[[#This Row],[Fecha llegada]],"MMM"))) -> FEB | C11: =YEAR(Tabla3[[#This Row],[Fecha llegada]]) -> 2024 | D11: Loc. 1001-1044 Plat.4060,4102,4083,4068,4087,4048,4073,4010,4007,4103,4053,4071,4095,4061 | E11: 45323 | F11: 45324 | G11: 2 | H11: 2 | I11: 853498.11 | J11: 14 | K11: 571220.7 | L11: 1424718.8 | M11: 390.78 | N11: 257 | O11: =M11*N11 -> 100430.46 | P11: 878003.25 | Q11: REMISION ARGOS RPSM-00301406 | R11: 614 | S11: 491.2 | T11: 4015324.2 | U11: OC009
A12: 11 | B12: =UPPER((TEXT(Tabla3[[#This Row],[Fecha llegada]],"MMM"))) -> FEB | C12: =YEAR(Tabla3[[#This Row],[Fecha llegada]]) -> 2024 | D12: Loc. 1001-1044 Plat. 4159,4162,4104,4151,4146,4120,4124 | E12: 45333 | F12: 45334 | G12: 1 | H12: 0 | J12: 7 | K12: 316591.02 | L12: 316591.02 | M12: 246.78 | N12: 212.6 | O12: =M12*N12 -> 52465.428 | P12: 458673.76 | Q12: T1-67 | R12: 212.6 | S12: 170.08 | T12: 1390322.4 | U12: OC009
A13: 12 | B13: =UPPER((TEXT(Tabla3[[#This Row],[Fecha llegada]],"MMM"))) -> FEB | C13: =YEAR(Tabla3[[#This Row],[Fecha llegada]]) -> 2024 | D13: Loc. 1001-1044 Plat. 4060,4063,4068,4002,4018,4003,4049,4124,4120,4146, 4151,4104,4162,4159 | E13: 45334 | F13: 45335 | G13: 2 | H13: 2 | I13: 853498.11 | J13: 14 | K13: 571220.7 | L13: 1424718.8 | M13: 389.55 | N13: 257 | O13: =M13*N13 -> 100114.35 | P13: 875239.69 | Q13: REMISION ARGOS RPSM-00302182 | R13: 357 | S13: 285.6 | T13: 2334642.9 | U13: OC009
